#VRML_SIM R2020b utf8
WorldInfo {
  basicTimeStep 5
  coordinateSystem "NUE"
}
Viewpoint {
  orientation -0.0062374229171470235 0.9654003531898293 0.2606976267945406 3.095404739877861
  position 0.04181576086445957 0.5838362125539888 -0.9131814281246056
}
TexturedBackground {
}
TexturedBackgroundLight {
}
RectangleArena {
  floorSize 10 10
}
DEF ROBOT Robot {
  translation 0.117707 0.04 -0.286743
  children [
    Accelerometer {
      translation 0 0.06 0
      children [
        Shape {
          appearance PBRAppearance {
            baseColor 0.333333 1 1
            metalness 0
          }
          geometry DEF ACCELEROMETER Box {
            size 0.01 0.01 0.01
          }
        }
      ]
      boundingObject USE ACCELEROMETER
    }
    InertialUnit {
      translation 0 0.03 0
      rotation 0 1 0 -1.57
      children [
        Shape {
          appearance PBRAppearance {
            baseColor 1 1 0
            metalness 0
          }
          geometry DEF IMU Box {
            size 0.01 0.01 0.01
          }
        }
      ]
      name "imu"
    }
    Gyro {
      translation 0 0.05 0
      children [
        Shape {
          appearance PBRAppearance {
            baseColor 0.333333 1 0
            metalness 0
          }
          geometry DEF GYRO Box {
            size 0.01 0.01 0.01
          }
        }
      ]
      boundingObject USE GYRO
    }
    GPS {
      translation 0 0.04 0
      children [
        Shape {
          appearance PBRAppearance {
            baseColor 0.333333 0 1
            metalness 0
          }
          geometry DEF GPS Box {
            size 0.01 0.01 0.01
          }
        }
      ]
      boundingObject USE GPS
    }
    Lidar {
      translation 0 0.03 0.09
      rotation 0 1 0 3.141592653589793
      children [
        Shape {
          appearance PBRAppearance {
            baseColor 0 0 1
            metalness 0
          }
          geometry DEF LIDAR Box {
            size 0.01 0.01 0.01
          }
        }
      ]
      tiltAngle -0.12
      fieldOfView 1.57
      numberOfLayers 10
      maxRange 4
    }
    DEF BODY Shape {
      appearance PBRAppearance {
        baseColor 1 0 0
        metalness 0
      }
      geometry Box {
        size 0.1 0.05 0.2
      }
    }
    HingeJoint {
      jointParameters HingeJointParameters {
        anchor 0.06 0 0.05
      }
      device [
        RotationalMotor {
          name "wheel1"
        }
      ]
      endPoint DEF WHEEL1 Solid {
        translation 0.06005186559358913 -3.157723486129075e-05 0.0500207526884499
        rotation 0.011355480419242383 -0.014724716484270891 -0.9998271029477577 4.708723537184392
        children [
          DEF WHEEL Shape {
            appearance PBRAppearance {
              baseColor 0 1 0
              metalness 0
            }
            geometry Cylinder {
              height 0.02
              radius 0.04
            }
          }
        ]
        boundingObject USE WHEEL
        physics DEF WHEEL_PH Physics {
        }
      }
    }
    HingeJoint {
      jointParameters HingeJointParameters {
        anchor -0.06 0 0.05
      }
      device [
        RotationalMotor {
          name "wheel2"
        }
      ]
      endPoint DEF WHEEL2 Solid {
        translation -0.06000627491628889 -1.1261465698166471e-05 0.05001037499794944
        rotation 0.006888329611843957 -0.006479269089461786 -0.9999552839938518 4.7078475462419815
        children [
          USE WHEEL
        ]
        name "solid(1)"
        boundingObject USE WHEEL
        physics USE WHEEL_PH
      }
    }
    HingeJoint {
      jointParameters HingeJointParameters {
        anchor 0.06 0 -0.05
      }
      device [
        RotationalMotor {
          name "wheel3"
        }
      ]
      endPoint DEF WHEEL3 Solid {
        translation 0.06000581021086107 2.7169818866217477e-06 -0.04998451417276848
        rotation 0.011355081800713616 -0.01472505624181835 -0.9998271024712094 4.708722744097527
        children [
          USE WHEEL
        ]
        name "solid(2)"
        boundingObject USE WHEEL
        physics USE WHEEL_PH
      }
    }
    HingeJoint {
      jointParameters HingeJointParameters {
        anchor -0.06 0 -0.05
      }
      device [
        RotationalMotor {
          name "wheel4"
        }
      ]
      endPoint DEF WHEEL4 Solid {
        translation -0.060051451242279466 1.2015803057747292e-05 -0.04996466295142506
        rotation 0.006888333402824968 -0.006479218054907053 -0.9999552842984172 4.707846319313928
        children [
          USE WHEEL
        ]
        name "solid(3)"
        boundingObject USE WHEEL
        physics USE WHEEL_PH
      }
    }
  ]
  boundingObject USE BODY
  physics Physics {
  }
  controller "circle_track_controller"
  controllerArgs [
    ""
  ]
  supervisor TRUE
}
DEF CONES Transform {
  scale 0.06 0.06 0.06
  children [
    TrafficCone {
      translation -6.26972 0 4.46565
      name "yellow cone(0)"
      physics Physics {
      }
    }
    TrafficCone {
      translation -3.333 0 2.36817
      name "yellow cone(1)"
      physics Physics {
      }
    }
    TrafficCone {
      translation 3.35465 0 4.2979
      name "blue cone(2)"
      physics Physics {
      }
    }
    TrafficCone {
      translation -10.4731 0 12.5632
      name "blue cone(3)"
      physics Physics {
      }
    }
    TrafficCone {
      translation -1.17581 0 0.255439
      name "yellow cone(4)"
      physics Physics {
      }
    }
    TrafficCone {
      translation -7.57492 0 11.5234
      name "blue cone(5)"
      physics Physics {
      }
    }
    TrafficCone {
      translation -3.78669 0 9.63622
      name "blue cone(6)"
      physics Physics {
      }
    }
    TrafficCone {
      translation -0.410606 0 7.53441
      name "blue cone(7)"
      physics Physics {
      }
    }
    TrafficCone {
      translation -9.82373 0 5.93449
      name "yellow cone(8)"
      physics Physics {
      }
    }
    TrafficCone {
      translation -29.9815 0 -3.50641
      name "blue cone(9)"
      physics Physics {
      }
    }
    TrafficCone {
      translation -14.534 0 -14.3585
      name "yellow cone(10)"
      physics Physics {
      }
    }
    TrafficCone {
      translation -14.6447 0 -21.9842
      name "blue cone(11)"
      physics Physics {
      }
    }
    TrafficCone {
      translation -8.90417 0 -12.0795
      name "yellow cone(12)"
      physics Physics {
      }
    }
    TrafficCone {
      translation -1.7718 0 -4.44292
      name "yellow cone(13)"
      physics Physics {
      }
    }
    TrafficCone {
      translation -4.35867 0 -19.7046
      name "blue cone(14)"
      physics Physics {
      }
    }
    TrafficCone {
      translation -0.670367 0 -17.1538
      name "blue cone(15)"
      physics Physics {
      }
    }
    TrafficCone {
      translation -8.99027 0 -20.7649
      name "blue cone(16)"
      physics Physics {
      }
    }
    TrafficCone {
      translation -4.89902 0 -8.856400000000002
      name "yellow cone(17)"
      physics Physics {
      }
    }
    TrafficCone {
      translation 5.11397 0 -4.73873
      name "blue cone(18)"
      physics Physics {
      }
    }
    TrafficCone {
      translation 2.39008 0 -13.6389
      name "blue cone(19)"
      physics Physics {
      }
    }
    TrafficCone {
      translation 4.18513 0 -9.36252
      name "blue cone(20)"
      physics Physics {
      }
    }
    TrafficCone {
      translation -23.6709 0 -3.63542
      name "yellow cone(21)"
      physics Physics {
      }
    }
    TrafficCone {
      translation -22.363 0 -6.70901
      name "yellow cone(22)"
      physics Physics {
      }
    }
    TrafficCone {
      translation -17.8806 0 -11.7611
      name "yellow cone(23)"
      physics Physics {
      }
    }
    TrafficCone {
      translation -20.1937 0 -9.31417
      name "yellow cone(24)"
      physics Physics {
      }
    }
    TrafficCone {
      translation -26.213 0 -14.483400000000001
      name "blue cone(25)"
      physics Physics {
      }
    }
    TrafficCone {
      translation -19.702299999999997 0 -20.8831
      name "blue cone(26)"
      physics Physics {
      }
    }
    TrafficCone {
      translation -29.404600000000002 0 -8.11412
      name "blue cone(27)"
      physics Physics {
      }
    }
    TrafficCone {
      translation -23.7336 0 -17.9538
      name "blue cone(28)"
      physics Physics {
      }
    }
    TrafficCone {
      translation -28.0375 0 -11.9016
      name "blue cone(29)"
      physics Physics {
      }
    }
    TrafficCone {
      translation 4.99502 0 0.304143
      name "blue cone(30)"
      physics Physics {
      }
    }
    TrafficCone {
      translation -13.8918 0 13.1271
      name "blue cone(31)"
      physics Physics {
      }
    }
    TrafficCone {
      translation -22.0842 0 -0.0919513
      name "yellow cone(32)"
      physics Physics {
      }
    }
    TrafficCone {
      translation -19.4199 0 3.18091
      name "yellow cone(33)"
      physics Physics {
      }
    }
    TrafficCone {
      translation -16.9211 0 5.27127
      name "yellow cone(34)"
      physics Physics {
      }
    }
    TrafficCone {
      translation -18.2173 0 11.8123
      name "blue cone(35)"
      physics Physics {
      }
    }
    TrafficCone {
      translation -21.4712 0 9.28383
      name "blue cone(36)"
      physics Physics {
      }
    }
    TrafficCone {
      translation -24.2471 0 6.06671
      name "blue cone(37)"
      physics Physics {
      }
    }
    TrafficCone {
      translation -26.6594 0 3.03566
      name "blue cone(38)"
      physics Physics {
      }
    }
    TrafficCone {
      translation -13.9505 0 6.515059999999999
      name "yellow cone(39)"
      physics Physics {
      }
    }
    TrafficCone {
      translation -28.3291 0 -0.157396
      name "blue cone(40)"
      physics Physics {
      }
    }
  ]
}
